Sending build context to Docker daemon  14.85kB
Step 1/5 : FROM python:3.9-slim
 ---> 4602238ffbdc
Step 2/5 : WORKDIR /app
 ---> Using cache
 ---> 36f5c2d4504c
Step 3/5 : COPY tests/auth_test.py /app
 ---> Using cache
 ---> bfdac560b2c6
Step 4/5 : RUN pip3 install --upgrade pip && pip3 install requests
 ---> Running in aa007eacfeb6
Requirement already satisfied: pip in /usr/local/lib/python3.9/site-packages (23.0.1)
Collecting pip
  Downloading pip-24.0-py3-none-any.whl (2.1 MB)
ERROR: Exception:
Traceback (most recent call last):
  File "/usr/local/lib/python3.9/site-packages/pip/_internal/cli/base_command.py", line 160, in exc_logging wrapper
    status = run_func(*args)
  File "/usr/local/lib/python3.9/site-packages/pip/_internal/cli/req_command.py", line 247, in wrapper
    return func(self, options, args)
  File "/usr/local/lib/python3.9/site-packages/pip/_internal/commands/install.py", line 419, in run
    requirement_set = resolver.resolve(
  File "/usr/local/lib/python3.9/site-packages/pip/_internal/resolution/resolvelib/resolver.py", line 92, in resolve
    result = self._result = resolver.resolve(
  File "/usr/local/lib/python3.9/site-packages/pip/_vendor/resolvelib/resolvers.py", line 481, in resolve
    state = resolution.resolve(requirements, max_rounds=max_rounds)
  File "/usr/local/lib/python3.9/site-packages/pip/_vendor/resolvelib/resolvers.py", line 348, in resolve
    self._add_to_criteria(self.state.criteria, r, parent=None)
  File "/usr/local/lib/python3.9/site-packages/pip/_vendor/resolvelib/resolvers.py", line 172, in _add_to_criteria
    if not criterion.candidates:
  File "/usr/local/lib/python3.9/site-packages/pip/_vendor/resolvelib/structs.py", line 151, in __bool__
    return bool(self._sequence)
  File "/usr/local/lib/python3.9/site-packages/pip/_internal/resolution/resolvelib/found_candidates.py", line 155, in __bool__
    return any(self)
  File "/usr/local/lib/python3.9/site-packages/pip/_internal/resolution/resolvelib/found_candidates.py", line 143, in <genexpr>
    return (c for c in iterator if id(c) not in self._incompatible_ids)
  File "/usr/local/lib/python3.9/site-packages/pip/_internal/resolution/resolvelib/found_candidates.py", line 97, in _iter_built_with_inserted
    candidate = func()
  File "/usr/local/lib/python3.9/site-packages/pip/_internal/resolution/resolvelib/factory.py", line 206, in _make_candidate_from_link
    self._link_candidate_cache[link] = LinkCandidate(
  File "/usr/local/lib/python3.9/site-packages/pip/_internal/resolution/resolvelib/candidates.py", line 297, in __init__
    super().__init__(
  File "/usr/local/lib/python3.9/site-packages/pip/_internal/resolution/resolvelib/candidates.py", line 162, in __init__
    self.dist = self._prepare()
  File "/usr/local/lib/python3.9/site-packages/pip/_internal/resolution/resolvelib/candidates.py", line 231, in _prepare
    dist = self._prepare_distribution()
  File "/usr/local/lib/python3.9/site-packages/pip/_internal/resolution/resolvelib/candidates.py", line 308, in _prepare_distribution
    return preparer.prepare_linked_requirement(self._ireq, parallel_builds=True)
  File "/usr/local/lib/python3.9/site-packages/pip/_internal/operations/prepare.py", line 491, in prepare_linked_requirement
    return self._prepare_linked_requirement(req, parallel_builds)
  File "/usr/local/lib/python3.9/site-packages/pip/_internal/operations/prepare.py", line 536, in _prepare_linked_requirement
    local_file = unpack_url(
  File "/usr/local/lib/python3.9/site-packages/pip/_internal/operations/prepare.py", line 166, in unpack_url
    file = get_http_url(
  File "/usr/local/lib/python3.9/site-packages/pip/_internal/operations/prepare.py", line 107, in get_http_url
    from_path, content_type = download(link, temp_dir.path)
  File "/usr/local/lib/python3.9/site-packages/pip/_internal/network/download.py", line 147, in __call__
    for chunk in chunks:
  File "/usr/local/lib/python3.9/site-packages/pip/_internal/cli/progress_bars.py", line 52, in _rich_progress_bar
    with progress:
  File "/usr/local/lib/python3.9/site-packages/pip/_vendor/rich/progress.py", line 1169, in __enter__
    self.start()
  File "/usr/local/lib/python3.9/site-packages/pip/_vendor/rich/progress.py", line 1160, in start
    self.live.start(refresh=True)
  File "/usr/local/lib/python3.9/site-packages/pip/_vendor/rich/live.py", line 132, in start
    self._refresh_thread.start()
  File "/usr/local/lib/python3.9/threading.py", line 899, in start
    _start_new_thread(self._bootstrap, ())
RuntimeError: can't start new thread

[notice] A new release of pip is available: 23.0.1 -> 24.0
[notice] To update, run: pip install --upgrade pip
The command '/bin/sh -c pip3 install --upgrade pip && pip3 install requests' returned a non-zero
